Workbook

Sheet Summary
A1: B16 dataset summary - every number below is a formula over the other sheets
A3: Instances per pattern and version (patterns_evolution)
A4: pattern | B4: Original code | C4: Code after Change3 | D4: Code after Change1 | E4: Code after Change2
A5: Adapter | B5: =COUNTIFS(patterns_evolution!$A:$A,B$4,patterns_evolution!$B:$B,$A5) | C5: =COUNTIFS(patterns_evolution!$A:$A,C$4,patterns_evolution!$B:$B,$A5) | D5: =COUNTIFS(patterns_evolution!$A:$A,D$4,patterns_evolution!$B:$B,$A5) | E5: =COUNTIFS(patterns_evolution!$A:$A,E$4,patterns_evolution!$B:$B,$A5)
A6: Chain of Responsibility | B6: =COUNTIFS(patterns_evolution!$A:$A,B$4,patterns_evolution!$B:$B,$A6) | C6: =COUNTIFS(patterns_evolution!$A:$A,C$4,patterns_evolution!$B:$B,$A6) | D6: =COUNTIFS(patterns_evolution!$A:$A,D$4,patterns_evolution!$B:$B,$A6) | E6: =COUNTIFS(patterns_evolution!$A:$A,E$4,patterns_evolution!$B:$B,$A6)
A7: Command | B7: =COUNTIFS(patterns_evolution!$A:$A,B$4,patterns_evolution!$B:$B,$A7) | C7: =COUNTIFS(patterns_evolution!$A:$A,C$4,patterns_evolution!$B:$B,$A7) | D7: =COUNTIFS(patterns_evolution!$A:$A,D$4,patterns_evolution!$B:$B,$A7) | E7: =COUNTIFS(patterns_evolution!$A:$A,E$4,patterns_evolution!$B:$B,$A7)
A8: Composite | B8: =COUNTIFS(patterns_evolution!$A:$A,B$4,patterns_evolution!$B:$B,$A8) | C8: =COUNTIFS(patterns_evolution!$A:$A,C$4,patterns_evolution!$B:$B,$A8) | D8: =COUNTIFS(patterns_evolution!$A:$A,D$4,patterns_evolution!$B:$B,$A8) | E8: =COUNTIFS(patterns_evolution!$A:$A,E$4,patterns_evolution!$B:$B,$A8)
A9: Decorator | B9: =COUNTIFS(patterns_evolution!$A:$A,B$4,patterns_evolution!$B:$B,$A9) | C9: =COUNTIFS(patterns_evolution!$A:$A,C$4,patterns_evolution!$B:$B,$A9) | D9: =COUNTIFS(patterns_evolution!$A:$A,D$4,patterns_evolution!$B:$B,$A9) | E9: =COUNTIFS(patterns_evolution!$A:$A,E$4,patterns_evolution!$B:$B,$A9)
A10: Factory Method | B10: =COUNTIFS(patterns_evolution!$A:$A,B$4,patterns_evolution!$B:$B,$A10) | C10: =COUNTIFS(patterns_evolution!$A:$A,C$4,patterns_evolution!$B:$B,$A10) | D10: =COUNTIFS(patterns_evolution!$A:$A,D$4,patterns_evolution!$B:$B,$A10) | E10: =COUNTIFS(patterns_evolution!$A:$A,E$4,patterns_evolution!$B:$B,$A10)
A11: Null Object | B11: =COUNTIFS(patterns_evolution!$A:$A,B$4,patterns_evolution!$B:$B,$A11) | C11: =COUNTIFS(patterns_evolution!$A:$A,C$4,patterns_evolution!$B:$B,$A11) | D11: =COUNTIFS(patterns_evolution!$A:$A,D$4,patterns_evolution!$B:$B,$A11) | E11: =COUNTIFS(patterns_evolution!$A:$A,E$4,patterns_evolution!$B:$B,$A11)
A12: Observer | B12: =COUNTIFS(patterns_evolution!$A:$A,B$4,patterns_evolution!$B:$B,$A12) | C12: =COUNTIFS(patterns_evolution!$A:$A,C$4,patterns_evolution!$B:$B,$A12) | D12: =COUNTIFS(patterns_evolution!$A:$A,D$4,patterns_evolution!$B:$B,$A12) | E12: =COUNTIFS(patterns_evolution!$A:$A,E$4,patterns_evolution!$B:$B,$A12)
A13: Strategy | B13: =COUNTIFS(patterns_evolution!$A:$A,B$4,patterns_evolution!$B:$B,$A13) | C13: =COUNTIFS(patterns_evolution!$A:$A,C$4,patterns_evolution!$B:$B,$A13) | D13: =COUNTIFS(patterns_evolution!$A:$A,D$4,patterns_evolution!$B:$B,$A13) | E13: =COUNTIFS(patterns_evolution!$A:$A,E$4,patterns_evolution!$B:$B,$A13)
A14: Template Method | B14: =COUNTIFS(patterns_evolution!$A:$A,B$4,patterns_evolution!$B:$B,$A14) | C14: =COUNTIFS(patterns_evolution!$A:$A,C$4,patterns_evolution!$B:$B,$A14) | D14: =COUNTIFS(patterns_evolution!$A:$A,D$4,patterns_evolution!$B:$B,$A14) | E14: =COUNTIFS(patterns_evolution!$A:$A,E$4,patterns_evolution!$B:$B,$A14)
A15: total instances | B15: =SUM(B5:B14) | C15: =SUM(C5:C14) | D15: =SUM(D5:D14) | E15: =SUM(E5:E14)
A16: pattern types | B16: =COUNTIF(B5:B14,">0") | C16: =COUNTIF(C5:C14,">0") | D16: =COUNTIF(D5:D14,">0") | E16: =COUNTIF(E5:E14,">0")
A17: check: total in pattern_counts | B17: =SUMIFS(pattern_counts!$D:$D,pattern_counts!$A:$A,B$4,pattern_counts!$B:$B,"total_pattern_instances") | C17: =SUMIFS(pattern_counts!$D:$D,pattern_counts!$A:$A,C$4,pattern_counts!$B:$B,"total_pattern_instances") | D17: =SUMIFS(pattern_counts!$D:$D,pattern_counts!$A:$A,D$4,pattern_counts!$B:$B,"total_pattern_instances") | E17: =SUMIFS(pattern_counts!$D:$D,pattern_counts!$A:$A,E$4,pattern_counts!$B:$B,"total_pattern_instances")
A19: Status after change, per version
A20: status | B20: =B4 | C20: =C4 | D20: =D4 | E20: =E4
A21: baseline | B21: =COUNTIFS(patterns_evolution!$A:$A,B$20,patterns_evolution!$H:$H,$A21) | C21: =COUNTIFS(patterns_evolution!$A:$A,C$20,patterns_evolution!$H:$H,$A21) | D21: =COUNTIFS(patterns_evolution!$A:$A,D$20,patterns_evolution!$H:$H,$A21) | E21: =COUNTIFS(patterns_evolution!$A:$A,E$20,patterns_evolution!$H:$H,$A21)
A22: preserved | B22: =COUNTIFS(patterns_evolution!$A:$A,B$20,patterns_evolution!$H:$H,$A22) | C22: =COUNTIFS(patterns_evolution!$A:$A,C$20,patterns_evolution!$H:$H,$A22) | D22: =COUNTIFS(patterns_evolution!$A:$A,D$20,patterns_evolution!$H:$H,$A22) | E22: =COUNTIFS(patterns_evolution!$A:$A,E$20,patterns_evolution!$H:$H,$A22)
A23: modified | B23: =COUNTIFS(patterns_evolution!$A:$A,B$20,patterns_evolution!$H:$H,$A23) | C23: =COUNTIFS(patterns_evolution!$A:$A,C$20,patterns_evolution!$H:$H,$A23) | D23: =COUNTIFS(patterns_evolution!$A:$A,D$20,patterns_evolution!$H:$H,$A23) | E23: =COUNTIFS(patterns_evolution!$A:$A,E$20,patterns_evolution!$H:$H,$A23)
A24: extended | B24: =COUNTIFS(patterns_evolution!$A:$A,B$20,patterns_evolution!$H:$H,$A24) | C24: =COUNTIFS(patterns_evolution!$A:$A,C$20,patterns_evolution!$H:$H,$A24) | D24: =COUNTIFS(patterns_evolution!$A:$A,D$20,patterns_evolution!$H:$H,$A24) | E24: =COUNTIFS(patterns_evolution!$A:$A,E$20,patterns_evolution!$H:$H,$A24)
A25: replaced | B25: =COUNTIFS(patterns_evolution!$A:$A,B$20,patterns_evolution!$H:$H,$A25) | C25: =COUNTIFS(patterns_evolution!$A:$A,C$20,patterns_evolution!$H:$H,$A25) | D25: =COUNTIFS(patterns_evolution!$A:$A,D$20,patterns_evolution!$H:$H,$A25) | E25: =COUNTIFS(patterns_evolution!$A:$A,E$20,patterns_evolution!$H:$H,$A25)
A26: removed | B26: =COUNTIFS(patterns_evolution!$A:$A,B$20,patterns_evolution!$H:$H,$A26) | C26: =COUNTIFS(patterns_evolution!$A:$A,C$20,patterns_evolution!$H:$H,$A26) | D26: =COUNTIFS(patterns_evolution!$A:$A,D$20,patterns_evolution!$H:$H,$A26) | E26: =COUNTIFS(patterns_evolution!$A:$A,E$20,patterns_evolution!$H:$H,$A26)
A27: newly_introduced | B27: =COUNTIFS(patterns_evolution!$A:$A,B$20,patterns_evolution!$H:$H,$A27) | C27: =COUNTIFS(patterns_evolution!$A:$A,C$20,patterns_evolution!$H:$H,$A27) | D27: =COUNTIFS(patterns_evolution!$A:$A,D$20,patterns_evolution!$H:$H,$A27) | E27: =COUNTIFS(patterns_evolution!$A:$A,E$20,patterns_evolution!$H:$H,$A27)
A29: Cross-language (cross_language): average over the two patterns
A30: language | B30: avg source_loc | C30: max function CC | D30: avg median ms | E30: programs
A31: Java | B31: =AVERAGEIF(cross_language!$C:$C,$A31,cross_language!$E:$E) | C31: =SUMPRODUCT(MAX((cross_language!$C$2:$C$9=$A31)*cross_language!$F$2:$F$9)) | D31: =AVERAGEIF(cross_language!$C:$C,$A31,cross_language!$J:$J) | E31: =COUNTIF(cross_language!$C:$C,$A31)
A32: Python | B32: =AVERAGEIF(cross_language!$C:$C,$A32,cross_language!$E:$E) | C32: =SUMPRODUCT(MAX((cross_language!$C$2:$C$9=$A32)*cross_language!$F$2:$F$9)) | D32: =AVERAGEIF(cross_language!$C:$C,$A32,cross_language!$J:$J) | E32: =COUNTIF(cross_language!$C:$C,$A32)
A33: JavaScript | B33: =AVERAGEIF(cross_language!$C:$C,$A33,cross_language!$E:$E) | C33: =SUMPRODUCT(MAX((cross_language!$C$2:$C$9=$A33)*cross_language!$F$2:$F$9)) | D33: =AVERAGEIF(cross_language!$C:$C,$A33,cross_language!$J:$J) | E33: =COUNTIF(cross_language!$C:$C,$A33)
A34: C++ | B34: =AVERAGEIF(cross_language!$C:$C,$A34,cross_language!$E:$E) | C34: =SUMPRODUCT(MAX((cross_language!$C$2:$C$9=$A34)*cross_language!$F$2:$F$9)) | D34: =AVERAGEIF(cross_language!$C:$C,$A34,cross_language!$J:$J) | E34: =COUNTIF(cross_language!$C:$C,$A34)
A36: LLM claim verification
A37: verdict | B37: Part 1 | C37: Part 2 | D37: Part 3
A38: correct | B38: =COUNTIF(verification_part1!$E:$E,$A38) | C38: =COUNTIF(verification_part2!$E:$E,$A38) | D38: =COUNTIF(verification_part3!$E:$E,$A38)
A39: partially correct | B39: =COUNTIF(verification_part1!$E:$E,$A39) | C39: =COUNTIF(verification_part2!$E:$E,$A39) | D39: =COUNTIF(verification_part3!$E:$E,$A39)
A40: incorrect* | B40: =COUNTIF(verification_part1!$E:$E,$A40) | C40: =COUNTIF(verification_part2!$E:$E,$A40) | D40: =COUNTIF(verification_part3!$E:$E,$A40)
A41: cannot confirm | B41: =COUNTIF(verification_part1!$E:$E,$A41) | C41: =COUNTIF(verification_part2!$E:$E,$A41) | D41: =COUNTIF(verification_part3!$E:$E,$A41)
A42: rows checked | B42: =COUNTA(verification_part1!$A:$A)-2 | C42: =COUNTA(verification_part2!$A:$A)-2 | D42: =COUNTA(verification_part3!$A:$A)-2
A43: rows checked = non-empty column A minus the header and the source note; 'incorrect*' also counts 'incorrect (proposed)'
A45: JUnit tests (test_counts)
...

Sheet patterns
A1: source_version | B1: pattern_name | C1: pattern_type | D1: instance_name | E1: participant_roles | F1: source_locations | G1: intent_and_evidence
A2: Original code | B2: Composite | C2: Structural | D2: A1 Test Descriptor Tree | E2: Component=org.junit.platform.engine.TestDescriptor; Composite (base)=org.junit.platform.engine.support.descriptor.AbstractTestDescriptor; Composite=org.junit.platform.engine.support.descriptor.EngineDescriptor; Composite=org.junit.jupiter.engine.descriptor.JupiterEngineDescriptor; Composite=org.junit.jupiter.engine.descriptor.ClassTestDescriptor; Composite=org.junit.jupiter.engine.descriptor.NestedClassTestDescriptor; Composite=org.junit.jupiter.engine.descriptor.ClassTemplateTestDescriptor; Composite=org.junit.jupiter.engine.descriptor.ClassTemplateInvocationTestDescriptor; Composite=org.junit.jupiter.engine.descriptor.TestTemplateTestDescriptor; Composite=org.junit.jupiter.engine.descriptor.TestFactoryTestDescriptor; Composite=org.junit.jupiter.engine.descriptor.DynamicContainerTestDescriptor; Leaf=org.junit.jupiter.engine.descriptor.TestMethodTestDescriptor; Leaf=org.junit.jupiter.engine.descriptor.TestTemplateInvocationTestDescriptor; Leaf=org.junit.jupiter.engine.descriptor.DynamicTestTestDescriptor; Client=org.junit.platform.launcher.core.EngineDiscoveryOrchestrator#applyPostDiscoveryFilters; Client=org.junit.platform.engine.support.hierarchical.NodeTestTask#executeRecursively | F2: data/code/junit-platform-engine/src/main/java/org/junit/platform/engine/TestDescriptor.java:37-427; data/code/junit-platform-engine/src/main/java/org/junit/platform/engine/support/descriptor/AbstractTestDescriptor.java:42-248; data/code/junit-platform-engine/src/main/java/org/junit/platform/engine/support/descriptor/EngineDescriptor.java:25-53; data/code/junit-jupiter-engine/src/main/java/org/junit/jupiter/engine/descriptor/JupiterEngineDescriptor.java:30-70; data/code/junit-jupiter-engine/src/main/java/org/junit/jupiter/engine/descriptor/ClassTestDescriptor.java:47-106; data/code/junit-jupiter-engine/src/main/java/org/junit/jupiter/engine/descriptor/NestedClassTestDescriptor.java:49-121; data/code/junit-jupiter-engine/src/main/java/org/junit/jupiter/engine/descriptor/ClassTemplateTestDescriptor.java:51-277; data/code/junit-jupiter-engine/src/main/java/org/junit/jupiter/engine/descriptor/ClassTemplateInvocationTestDescriptor.java:48-202; data/code/junit-jupiter-engine/src/main/java/org/junit/jupiter/engine/descriptor/TestTemplateTestDescriptor.java:41-167; data/code/junit-jupiter-engine/src/main/java/org/junit/jupiter/engine/descriptor/TestFactoryTestDescriptor.java:56-223; data/code/junit-jupiter-engine/src/main/java/org/junit/jupiter/engine/descriptor/DynamicContainerTestDescriptor.java:34-88; data/code/junit-jupiter-engine/src/main/java/org/junit/jupiter/engine/descriptor/TestMethodTestDescriptor.java:71-293; data/code/junit-jupiter-engine/src/main/java/org/junit/jupiter/engine/descriptor/TestTemplateInvocationTestDescriptor.java:42-104; data/code/junit-jupiter-engine/src/main/java/org/junit/jupiter/engine/descriptor/DynamicTestTestDescriptor.java:37-100; data/code/junit-platform-launcher/src/main/java/org/junit/platform/launcher/core/EngineDiscoveryOrchestrator.java:225-238; data/code/junit-platform-engine/src/main/java/org/junit/platform/engine/support/hierarchical/NodeTestTask.java:157-189 | G2: Engines build one tree of TestDescriptor nodes (engine > class > nested class > method > dynamic test); the launcher filters, prunes, visits and executes it without knowing node kinds. Evidence: TestDescriptor.accept visits itself then calls child.accept(visitor); AbstractTestDescriptor holds the children set and findByUniqueId recurses; NodeTestTask creates one child task per child. Transparent variant: leaf vs container is decided by getType().
A3: Original code | B3: Composite | C3: Structural | D3: A2 Composed Discovery Filter | E3: Component=org.junit.platform.engine.Filter; Composite=org.junit.platform.engine.CompositeFilter; Leaf=org.junit.platform.launcher.IncludeMethodFilter; Leaf=org.junit.platform.launcher.ExcludeMethodFilter; Leaf (lambda factory)=org.junit.platform.launcher.TagFilter; Client=org.junit.platform.launcher.core.EngineDiscoveryOrchestrator#applyPostDiscoveryFilters | F3: data/code/junit-platform-engine/src/main/java/org/junit/platform/engine/Filter.java:41-119; data/code/junit-platform-engine/src/main/java/org/junit/platform/engine/CompositeFilter.java:29-89; data/code/junit-platform-launcher/src/main/java/org/junit/platform/launcher/IncludeMethodFilter.java:31-58; data/code/junit-platform-launcher/src/main/java/org/junit/platform/launcher/ExcludeMethodFilter.java:31-58; data/code/junit-platform-launcher/src/main/java/org/junit/platform/launcher/TagFilter.java:48-184; data/code/junit-platform-launcher/src/main/java/org/junit/platform/launcher/core/EngineDiscoveryOrchestrator.java:225-238 | G3: All post-discovery filters are merged into one Filter by Filter.composeFilters; CompositeFilter implements Filter, holds a list of Filters and combines their FilterResults into one answer (first exclusion wins). Overlaps A3 (same leaf classes seen as strategies).
A4: Original code | B4: Strategy | C4: Behavioral | D4: A3 Post-Discovery Filter Policies | E4: Strategy=org.junit.platform.launcher.PostDiscoveryFilter; ConcreteStrategy=org.junit.platform.launcher.IncludeMethodFilter; ConcreteStrategy=org.junit.platform.launcher.ExcludeMethodFilter; ConcreteStrategy (lambdas)=org.junit.platform.launcher.TagFilter; Context=org.junit.platform.launcher.core.EngineDiscoveryOrchestrator#applyPostDiscoveryFilters | F4: data/code/junit-platform-launcher/src/main/java/org/junit/platform/launcher/PostDiscoveryFilter.java:35-36; data/code/junit-platform-launcher/src/main/java/org/junit/platform/launcher/IncludeMethodFilter.java:31-58; data/code/junit-platform-launcher/src/main/java/org/junit/platform/launcher/ExcludeMethodFilter.java:31-58; data/code/junit-platform-launcher/src/main/java/org/junit/platform/launcher/TagFilter.java:48-184; data/code/junit-platform-launcher/src/main/java/org/junit/platform/launcher/core/EngineDiscoveryOrchestrator.java:225-238 | G4: Selection rules (tag expressions, method-name patterns, custom filters) are interchangeable algorithms behind PostDiscoveryFilter; EngineDiscoveryOrchestrator only calls apply(). Overlaps A2.
A5: Original code | B5: Template Method | C5: Behavioral | D5: A4 Jupiter Descriptor Skeletons | E5: AbstractClass=org.junit.jupiter.engine.descriptor.JupiterTestDescriptor; TemplateMethod=org.junit.jupiter.engine.descriptor.JupiterTestDescriptor#getExecutionMode; TemplateMethod=org.junit.jupiter.engine.descriptor.JupiterTestDescriptor#getLegacyReportingName; TemplateMethod=org.junit.jupiter.engine.descriptor.JupiterTestDescriptor#copyIncludingDescendants; PrimitiveOperation=org.junit.jupiter.engine.descriptor.JupiterTestDescriptor#withUniqueId; ConcreteClass (hook)=org.junit.jupiter.engine.descriptor.ClassBasedTestDescriptor#getExplicitExecutionMode; ConcreteClass (hook)=org.junit.jupiter.engine.descriptor.MethodBasedTestDescriptor#getExplicitExecutionMode; ConcreteClass (primitive)=org.junit.jupiter.engine.descriptor.ClassTestDescriptor#withUniqueId | F5: data/code/junit-jupiter-engine/src/main/java/org/junit/jupiter/engine/descriptor/JupiterTestDescriptor.java:64-283; data/code/junit-jupiter-engine/src/main/java/org/junit/jupiter/engine/descriptor/JupiterTestDescriptor.java:163-167; data/code/junit-jupiter-engine/src/main/java/org/junit/jupiter/engine/descriptor/JupiterTestDescriptor.java:85-88; data/code/junit-jupiter-engine/src/main/java/org/junit/jupiter/engine/descriptor/JupiterTestDescriptor.java:256-263; data/code/junit-jupiter-engine/src/main/java/org/junit/jupiter/engine/descriptor/JupiterTestDescriptor.java:268-268; data/code/junit-jupiter-engine/src/main/java/org/junit/jupiter/engine/descriptor/ClassBasedTestDescriptor.java:167-169; data/code/junit-jupiter-engine/src/main/java/org/junit/jupiter/engine/descriptor/MethodBasedTestDescriptor.java:147-149; data/code/junit-jupiter-engine/src/main/java/org/junit/jupiter/engine/descriptor/ClassTestDescriptor.java:63-66 | G5: JupiterTestDescriptor fixes algorithms in final methods (getExecutionMode, getLegacyReportingName) and in copyIncludingDescendants, which calls the abstract primitive withUniqueId; subclasses override the hooks (getExplicitExecutionMode, getLegacyReportingBaseName, withUniqueId).
A6: Original code | B6: Template Method | C6: Behavioral | D6: A5 Child Ordering Skeleton | E6: AbstractClass=org.junit.jupiter.engine.discovery.AbstractOrderingVisitor; TemplateMethod=org.junit.jupiter.engine.discovery.AbstractOrderingVisitor#orderChildrenTestDescriptors; PrimitiveOperation=org.junit.jupiter.engine.discovery.AbstractOrderingVisitor#shouldNonMatchingDescriptorsComeBeforeOrderedOnes; ConcreteClass=org.junit.jupiter.engine.discovery.ClassOrderingVisitor; ConcreteClass=org.junit.jupiter.engine.discovery.MethodOrderingVisitor | F6: data/code/junit-jupiter-engine/src/main/java/org/junit/jupiter/engine/discovery/AbstractOrderingVisitor.java:39-222; data/code/junit-jupiter-engine/src/main/java/org/junit/jupiter/engine/discovery/AbstractOrderingVisitor.java:72-119; data/code/junit-jupiter-engine/src/main/java/org/junit/jupiter/engine/discovery/AbstractOrderingVisitor.java:126-126; data/code/junit-jupiter-engine/src/main/java/org/junit/jupiter/engine/discovery/ClassOrderingVisitor.java:38-165; data/code/junit-jupiter-engine/src/main/java/org/junit/jupiter/engine/discovery/MethodOrderingVisitor.java:41-174 | G6: AbstractOrderingVisitor.orderChildrenTestDescriptors runs a fixed ordering algorithm (select, wrap, sort, unwrap, merge) and asks the abstract hook shouldNonMatchingDescriptorsComeBeforeOrderedOnes, which ClassOrderingVisitor and MethodOrderingVisitor answer differently.
A7: Original code | B7: Observer | C7: Behavioral | D7: A6 Discovery Event Notification | E7: Observer=org.junit.platform.launcher.LauncherDiscoveryListener; Observer (base)=org.junit.platform.engine.EngineDiscoveryListener; ConcreteObserver=org.junit.platform.launcher.core.DiscoveryIssueCollector; ConcreteObserver=org.junit.platform.launcher.core.DiscoveryIssueReportingDiscoveryListener; Subject (attach)=org.junit.platform.launcher.core.DefaultLauncher#registerLauncherDiscoveryListeners; Subject (notify)=org.junit.platform.launcher.core.EngineDiscoveryOrchestrator#discoverEngineRoot; Subject (notify, in engine)=org.junit.platform.engine.support.discovery.EngineDiscoveryRequestResolution; Multicaster=org.junit.platform.launcher.listeners.discovery.CompositeLauncherDiscoveryListener | F7: data/code/junit-platform-launcher/src/main/java/org/junit/platform/launcher/LauncherDiscoveryListener.java:42-91; data/code/junit-platform-engine/src/main/java/org/junit/platform/engine/EngineDiscoveryListener.java:31-67; data/code/junit-platform-launcher/src/main/java/org/junit/platform/launcher/core/DiscoveryIssueCollector.java:25-65; data/code/junit-platform-launcher/src/main/java/org/junit/platform/launcher/core/DiscoveryIssueReportingDiscoveryListener.java:49-131; data/code/junit-platform-launcher/src/main/java/org/junit/platform/launcher/core/DefaultLauncher.java:73-77; data/code/junit-platform-launcher/src/main/java/org/junit/platform/launcher/core/EngineDiscoveryOrchestrator.java:189-214; data/code/junit-platform-engine/src/main/java/org/junit/platform/engine/support/discovery/EngineDiscoveryRequestResolution.java:60-263; data/code/junit-platform-launcher/src/main/java/org/junit/platform/launcher/listeners/discovery/CompositeLauncherDiscoveryListener.java:29-67 | G7: Discovery progress (launcher/engine discovery started and finished, selector processed, issues) is pushed to registered LauncherDiscoveryListeners that the orchestrator only knows by interface.
A8: Original code | B8: Adapter | C8: Structural | D8: A7 Orderer Descriptor Wrappers | E8: Target=org.junit.jupiter.api.ClassDescriptor; Target=org.junit.jupiter.api.MethodDescriptor; Adapter (base)=org.junit.jupiter.engine.discovery.AbstractAnnotatedDescriptorWrapper; Adapter=org.junit.jupiter.engine.discovery.DefaultClassDescriptor; Adapter=org.junit.jupiter.engine.discovery.DefaultMethodDescriptor; Adaptee=org.junit.jupiter.engine.descriptor.ClassBasedTestDescriptor; Adaptee=org.junit.jupiter.engine.descriptor.MethodBasedTestDescriptor; Client=org.junit.jupiter.engine.discovery.ClassOrderingVisitor | F8: data/code/junit-jupiter-api/src/main/java/org/junit/jupiter/api/ClassDescriptor.java:28-87; data/code/junit-jupiter-api/src/main/java/org/junit/jupiter/api/MethodDescriptor.java:29-90; data/code/junit-jupiter-engine/src/main/java/org/junit/jupiter/engine/discovery/AbstractAnnotatedDescriptorWrapper.java:28-65; data/code/junit-jupiter-engine/src/main/java/org/junit/jupiter/engine/discovery/DefaultClassDescriptor.java:23-39; data/code/junit-jupiter-engine/src/main/java/org/junit/jupiter/engine/discovery/DefaultMethodDescriptor.java:25-41; data/code/junit-jupiter-engine/src/main/java/org/junit/jupiter/engine/descriptor/ClassBasedTestDescriptor.java:89-601; data/code/junit-jupiter-engine/src/main/java/org/junit/jupiter/engine/descriptor/MethodBasedTestDescriptor.java:56-217; data/code/junit-jupiter-engine/src/main/java/org/junit/jupiter/engine/discovery/ClassOrderingVisitor.java:38-165 | G8: User ClassOrderer/MethodOrderer code expects the public ClassDescriptor/MethodDescriptor API; the wrappers expose internal descriptors through it so internal classes never leak to user code.
A9: Original code | B9: Template Method | C9: Behavioral | D9: B1 Hierarchical Engine Execution Skeleton | E9: AbstractClass=org.junit.platform.engine.support.hierarchical.HierarchicalTestEngine; TemplateMethod=org.junit.platform.engine.support.hierarchical.HierarchicalTestEngine#execute; PrimitiveOperation=org.junit.platform.engine.support.hierarchical.HierarchicalTestEngine#createExecutionContext; ConcreteClass=org.junit.jupiter.engine.JupiterTestEngine | F9: data/code/junit-platform-engine/src/main/java/org/junit/platform/engine/support/hierarchical/HierarchicalTestEngine.java:31-119; data/code/junit-platform-engine/src/main/java/org/junit/platform/engine/support/hierarchical/HierarchicalTestEngine.java:53-63; data/code/junit-platform-engine/src/main/java/org/junit/platform/engine/support/hierarchical/HierarchicalTestEngine.java:117-117; data/code/junit-jupiter-engine/src/main/java/org/junit/jupiter/engine/JupiterTestEngine.java:44-108 | G9: final HierarchicalTestEngine.execute fixes the run order (executor service, context, collector factory, HierarchicalTestExecutor); JupiterTestEngine only supplies the steps. Overlaps B2.
A10: Original code | B10: Factory Method | C10: Creational | D10: B2 Engine Collaborator Factory Methods | E10: Creator (factory method)=org.junit.platform.engine.support.hierarchical.HierarchicalTestEngine#createExecutorService; ConcreteCreator=org.junit.jupiter.engine.JupiterTestEngine#createExecutorService; ConcreteCreator=org.junit.jupiter.engine.JupiterTestEngine#createExecutionContext; ConcreteCreator=org.junit.jupiter.engine.JupiterTestEngine#createThrowableCollectorFactory; ConcreteProduct=org.junit.jupiter.engine.execution.JupiterEngineExecutionContext | F10: data/code/junit-platform-engine/src/main/java/org/junit/platform/engine/support/hierarchical/HierarchicalTestEngine.java:83-85; data/code/junit-jupiter-engine/src/main/java/org/junit/jupiter/engine/JupiterTestEngine.java:80-87; data/code/junit-jupiter-engine/src/main/java/org/junit/jupiter/engine/JupiterTestEngine.java:90-93; data/code/junit-jupiter-engine/src/main/java/org/junit/jupiter/engine/JupiterTestEngine.java:99-101; data/code/junit-jupiter-engine/src/main/java/org/junit/jupiter/engine/execution/JupiterEngineExecutionContext.java:30-209 | G10: The template in B1 asks overridable create* methods which objects to use; JupiterTestEngine overrides them to choose a parallel/same-thread executor, its JupiterEngineExecutionContext and its throwable-collector factory. Overlaps B1.
A11: Original code | B11: Strategy | C11: Behavioral | D11: B3 Test Executor Services | E11: Strategy=org.junit.platform.engine.support.hierarchical.HierarchicalTestExecutorService; ConcreteStrategy=org.junit.platform.engine.support.hierarchical.SameThreadHierarchicalTestExecutorService; ConcreteStrategy=org.junit.platform.engine.support.hierarchical.ForkJoinPoolHierarchicalTestExecutorService; ConcreteStrategy=org.junit.platform.engine.support.hierarchical.WorkerThreadPoolHierarchicalTestExecutorService; Context=org.junit.platform.engine.support.hierarchical.HierarchicalTestExecutor; Context=org.junit.platform.engine.support.hierarchical.NodeTestTask#executeRecursively | F11: data/code/junit-platform-engine/src/main/java/org/junit/platform/engine/support/hierarchical/HierarchicalTestExecutorService.java:34-118; data/code/junit-platform-engine/src/main/java/org/junit/platform/engine/support/hierarchical/SameThreadHierarchicalTestExecutorService.java:29-50; data/code/junit-platform-engine/src/main/java/org/junit/platform/engine/support/hierarchical/ForkJoinPoolHierarchicalTestExecutorService.java:51-331; data/code/junit-platform-engine/src/main/java/org/junit/platform/engine/support/hierarchical/WorkerThreadPoolHierarchicalTestExecutorService.java:70-901; data/code/junit-platform-engine/src/main/java/org/junit/platform/engine/support/hierarchical/HierarchicalTestExecutor.java:36-71; data/code/junit-platform-engine/src/main/java/org/junit/platform/engine/support/hierarchical/NodeTestTask.java:157-189 | G11: Sequential vs parallel scheduling is swappable behind HierarchicalTestExecutorService; NodeTestTask and HierarchicalTestExecutor only call submit/invokeAll.
A12: Original code | B12: Strategy | C12: Behavioral | D12: B4 Parallelism Configuration Strategy | E12: Strategy=org.junit.platform.engine.support.hierarchical.ParallelExecutionConfigurationStrategy; ConcreteStrategy (enum FIXED/DYNAMIC/CUSTOM)=org.junit.platform.engine.support.hierarchical.DefaultParallelExecutionConfigurationStrategy; Selection=org.junit.platform.engine.support.hierarchical.DefaultParallelExecutionConfigurationStrategy#getStrategy; Context=org.junit.platform.engine.support.hierarchical.ParallelHierarchicalTestExecutorServiceFactory | F12: data/code/junit-platform-engine/src/main/java/org/junit/platform/engine/support/hierarchical/ParallelExecutionConfigurationStrategy.java:25-33; data/code/junit-platform-engine/src/main/java/org/junit/platform/engine/support/hierarchical/DefaultParallelExecutionConfigurationStrategy.java:33-228; data/code/junit-platform-engine/src/main/java/org/junit/platform/engine/support/hierarchical/DefaultParallelExecutionConfigurationStrategy.java:223-226; data/code/junit-platform-engine/src/main/java/org/junit/platform/engine/support/hierarchical/ParallelHierarchicalTestExecutorServiceFactory.java:33-123 | G12: How parallelism is computed (FIXED, DYNAMIC from CPU count, CUSTOM user class) is chosen by configuration; each enum constant implements createConfiguration.
... A36: Original code | B36: Command | C36: Behavioral | D36: D11 Packaged Reflective Calls | E36: Command=org.junit.jupiter.api.extension.InvocationInterceptor.Invocation; ConcreteCommand=org.junit.jupiter.engine.execution.MethodInvocation; ConcreteCommand=org.junit.jupiter.engine.execution.ConstructorInvocation; Client=org.junit.jupiter.engine.execution.InterceptingExecutableInvoker | F36: data/code/junit-jupiter-api/src/main/java/org/junit/jupiter/api/extension/InvocationInterceptor.java:231-251; data/code/junit-jupiter-engine/src/main/java/org/junit/jupiter/engine/execution/MethodInvocation.java:25-64; data/code/junit-jupiter-engine/src/main/java/org/junit/jupiter/engine/execution/ConstructorInvocation.java:25-60; data/code/junit-jupiter-engine/src/main/java/org/junit/jupiter/engine/execution/InterceptingExecutableInvoker.java:40-137 | G36: A resolved reflective call (method or constructor + target + arguments) is packaged as an Invocation object so interceptors can run it later, on another thread, or skip it.
A38: Source: Part 1 instances at the baseline (generated by data/build_part1_csv.py)

Sheet pattern_counts
A1: source_version | B1: summary | C1: pattern_name | D1: count
A2: Original code | B2: per_pattern | C2: Adapter | D2: 5
A3: Original code | B3: per_pattern | C3: Chain of Responsibility | D3: 1
A4: Original code | B4: per_pattern | C4: Command | D4: 2
A5: Original code | B5: per_pattern | C5: Composite | D5: 2
A6: Original code | B6: per_pattern | C6: Decorator | D6: 4
A7: Original code | B7: per_pattern | C7: Factory Method | D7: 1
A8: Original code | B8: per_pattern | C8: Null Object | D8: 2
A9: Original code | B9: per_pattern | C9: Observer | D9: 5
A10: Original code | B10: per_pattern | C10: Strategy | D10: 10
A11: Original code | B11: per_pattern | C11: Template Method | D11: 3
A12: Original code | B12: total_pattern_types | D12: 10
A13: Original code | B13: total_pattern_instances | D13: 35
A14: Code after Change3 | B14: per_pattern | C14: Adapter | D14: 5
A15: Code after Change3 | B15: per_pattern | C15: Chain of Responsibility | D15: 1
A16: Code after Change3 | B16: per_pattern | C16: Command | D16: 2
A17: Code after Change3 | B17: per_pattern | C17: Composite | D17: 2
A18: Code after Change3 | B18: per_pattern | C18: Decorator | D18: 4
A19: Code after Change3 | B19: per_pattern | C19: Factory Method | D19: 1
A20: Code after Change3 | B20: per_pattern | C20: Null Object | D20: 2
A21: Code after Change3 | B21: per_pattern | C21: Observer | D21: 5
A22: Code after Change3 | B22: per_pattern | C22: Strategy | D22: 10
A23: Code after Change3 | B23: per_pattern | C23: Template Method | D23: 3
A24: Code after Change3 | B24: total_pattern_types | D24: 10
A25: Code after Change3 | B25: total_pattern_instances | D25: 35
A26: Code after Change1 | B26: per_pattern | C26: Adapter | D26: 5
A27: Code after Change1 | B27: per_pattern | C27: Chain of Responsibility | D27: 1
A28: Code after Change1 | B28: per_pattern | C28: Command | D28: 2
A29: Code after Change1 | B29: per_pattern | C29: Composite | D29: 2
A30: Code after Change1 | B30: per_pattern | C30: Decorator | D30: 4
A31: Code after Change1 | B31: per_pattern | C31: Factory Method | D31: 1
A32: Code after Change1 | B32: per_pattern | C32: Null Object | D32: 2
A33: Code after Change1 | B33: per_pattern | C33: Observer | D33: 5
A34: Code after Change1 | B34: per_pattern | C34: Strategy | D34: 10
A35: Code after Change1 | B35: per_pattern | C35: Template Method | D35: 3
A36: Code after Change1 | B36: total_pattern_types | D36: 10
A37: Code after Change1 | B37: total_pattern_instances | D37: 35
A38: Code after Change2 | B38: per_pattern | C38: Adapter | D38: 6
A39: Code after Change2 | B39: per_pattern | C39: Chain of Responsibility | D39: 1
A40: Code after Change2 | B40: per_pattern | C40: Command | D40: 2
...

Sheet patterns_evolution
A1: source_version | B1: pattern_name | C1: pattern_type | D1: instance_name | E1: participant_roles | F1: source_locations | G1: intent_and_evidence | H1: status_after_change | I1: change_description
A2: Original code | B2: Composite | C2: Structural | D2: A1 Test Descriptor Tree | E2: Component=org.junit.platform.engine.TestDescriptor; Composite (base)=org.junit.platform.engine.support.descriptor.AbstractTestDescriptor; Composite=org.junit.platform.engine.support.descriptor.EngineDescriptor; Composite=org.junit.jupiter.engine.descriptor.JupiterEngineDescriptor; Composite=org.junit.jupiter.engine.descriptor.ClassTestDescriptor; Composite=org.junit.jupiter.engine.descriptor.NestedClassTestDescriptor; Composite=org.junit.jupiter.engine.descriptor.ClassTemplateTestDescriptor; Composite=org.junit.jupiter.engine.descriptor.ClassTemplateInvocationTestDescriptor; Composite=org.junit.jupiter.engine.descriptor.TestTemplateTestDescriptor; Composite=org.junit.jupiter.engine.descriptor.TestFactoryTestDescriptor; Composite=org.junit.jupiter.engine.descriptor.DynamicContainerTestDescriptor; Leaf=org.junit.jupiter.engine.descriptor.TestMethodTestDescriptor; Leaf=org.junit.jupiter.engine.descriptor.TestTemplateInvocationTestDescriptor; Leaf=org.junit.jupiter.engine.descriptor.DynamicTestTestDescriptor; Client=org.junit.platform.launcher.core.EngineDiscoveryOrchestrator#applyPostDiscoveryFilters; Client=org.junit.platform.engine.support.hierarchical.NodeTestTask#executeRecursively | F2: data/code/junit-platform-engine/src/main/java/org/junit/platform/engine/TestDescriptor.java:37-427; data/code/junit-platform-engine/src/main/java/org/junit/platform/engine/support/descriptor/AbstractTestDescriptor.java:42-248; data/code/junit-platform-engine/src/main/java/org/junit/platform/engine/support/descriptor/EngineDescriptor.java:25-53; data/code/junit-jupiter-engine/src/main/java/org/junit/jupiter/engine/descriptor/JupiterEngineDescriptor.java:30-70; data/code/junit-jupiter-engine/src/main/java/org/junit/jupiter/engine/descriptor/ClassTestDescriptor.java:47-106; data/code/junit-jupiter-engine/src/main/java/org/junit/jupiter/engine/descriptor/NestedClassTestDescriptor.java:49-121; data/code/junit-jupiter-engine/src/main/java/org/junit/jupiter/engine/descriptor/ClassTemplateTestDescriptor.java:51-277; data/code/junit-jupiter-engine/src/main/java/org/junit/jupiter/engine/descriptor/ClassTemplateInvocationTestDescriptor.java:48-202; data/code/junit-jupiter-engine/src/main/java/org/junit/jupiter/engine/descriptor/TestTemplateTestDescriptor.java:41-167; data/code/junit-jupiter-engine/src/main/java/org/junit/jupiter/engine/descriptor/TestFactoryTestDescriptor.java:56-223; data/code/junit-jupiter-engine/src/main/java/org/junit/jupiter/engine/descriptor/DynamicContainerTestDescriptor.java:34-88; data/code/junit-jupiter-engine/src/main/java/org/junit/jupiter/engine/descriptor/TestMethodTestDescriptor.java:71-293; data/code/junit-jupiter-engine/src/main/java/org/junit/jupiter/engine/descriptor/TestTemplateInvocationTestDescriptor.java:42-104; data/code/junit-jupiter-engine/src/main/java/org/junit/jupiter/engine/descriptor/DynamicTestTestDescriptor.java:37-100; data/code/junit-platform-launcher/src/main/java/org/junit/platform/launcher/core/EngineDiscoveryOrchestrator.java:225-238; data/code/junit-platform-engine/src/main/java/org/junit/platform/engine/support/hierarchical/NodeTestTask.java:157-189 | G2: Engines build one tree of TestDescriptor nodes (engine > class > nested class > method > dynamic test); the launcher filters, prunes, visits and executes it without knowing node kinds. Evidence: TestDescriptor.accept visits itself then calls child.accept(visitor); AbstractTestDescriptor holds the children set and findByUniqueId recurses; NodeTestTask creates one child task per child. Transparent variant: leaf vs container is decided by getType(). | H2: baseline | I2: Instance as found in the original code (Part 1).
A3: Original code | B3: Composite | C3: Structural | D3: A2 Composed Discovery Filter | E3: Component=org.junit.platform.engine.Filter; Composite=org.junit.platform.engine.CompositeFilter; Leaf=org.junit.platform.launcher.IncludeMethodFilter; Leaf=org.junit.platform.launcher.ExcludeMethodFilter; Leaf (lambda factory)=org.junit.platform.launcher.TagFilter; Client=org.junit.platform.launcher.core.EngineDiscoveryOrchestrator#applyPostDiscoveryFilters | F3: data/code/junit-platform-engine/src/main/java/org/junit/platform/engine/Filter.java:41-119; data/code/junit-platform-engine/src/main/java/org/junit/platform/engine/CompositeFilter.java:29-89; data/code/junit-platform-launcher/src/main/java/org/junit/platform/launcher/IncludeMethodFilter.java:31-58; data/code/junit-platform-launcher/src/main/java/org/junit/platform/launcher/ExcludeMethodFilter.java:31-58; data/code/junit-platform-launcher/src/main/java/org/junit/platform/launcher/TagFilter.java:48-184; data/code/junit-platform-launcher/src/main/java/org/junit/platform/launcher/core/EngineDiscoveryOrchestrator.java:225-238 | G3: All post-discovery filters are merged into one Filter by Filter.composeFilters; CompositeFilter implements Filter, holds a list of Filters and combines their FilterResults into one answer (first exclusion wins). Overlaps A3 (same leaf classes seen as strategies). | H3: baseline | I3: Instance as found in the original code (Part 1).
A4: Original code | B4: Strategy | C4: Behavioral | D4: A3 Post-Discovery Filter Policies | E4: Strategy=org.junit.platform.launcher.PostDiscoveryFilter; ConcreteStrategy=org.junit.platform.launcher.IncludeMethodFilter; ConcreteStrategy=org.junit.platform.launcher.ExcludeMethodFilter; ConcreteStrategy (lambdas)=org.junit.platform.launcher.TagFilter; Context=org.junit.platform.launcher.core.EngineDiscoveryOrchestrator#applyPostDiscoveryFilters | F4: data/code/junit-platform-launcher/src/main/java/org/junit/platform/launcher/PostDiscoveryFilter.java:35-36; data/code/junit-platform-launcher/src/main/java/org/junit/platform/launcher/IncludeMethodFilter.java:31-58; data/code/junit-platform-launcher/src/main/java/org/junit/platform/launcher/ExcludeMethodFilter.java:31-58; data/code/junit-platform-launcher/src/main/java/org/junit/platform/launcher/TagFilter.java:48-184; data/code/junit-platform-launcher/src/main/java/org/junit/platform/launcher/core/EngineDiscoveryOrchestrator.java:225-238 | G4: Selection rules (tag expressions, method-name patterns, custom filters) are interchangeable algorithms behind PostDiscoveryFilter; EngineDiscoveryOrchestrator only calls apply(). Overlaps A2. | H4: baseline | I4: Instance as found in the original code (Part 1).
A5: Original code | B5: Template Method | C5: Behavioral | D5: A4 Jupiter Descriptor Skeletons | E5: AbstractClass=org.junit.jupiter.engine.descriptor.JupiterTestDescriptor; TemplateMethod=org.junit.jupiter.engine.descriptor.JupiterTestDescriptor#getExecutionMode; TemplateMethod=org.junit.jupiter.engine.descriptor.JupiterTestDescriptor#getLegacyReportingName; TemplateMethod=org.junit.jupiter.engine.descriptor.JupiterTestDescriptor#copyIncludingDescendants; PrimitiveOperation=org.junit.jupiter.engine.descriptor.JupiterTestDescriptor#withUniqueId; ConcreteClass (hook)=org.junit.jupiter.engine.descriptor.ClassBasedTestDescriptor#getExplicitExecutionMode; ConcreteClass (hook)=org.junit.jupiter.engine.descriptor.MethodBasedTestDescriptor#getExplicitExecutionMode; ConcreteClass (primitive)=org.junit.jupiter.engine.descriptor.ClassTestDescriptor#withUniqueId | F5: data/code/junit-jupiter-engine/src/main/java/org/junit/jupiter/engine/descriptor/JupiterTestDescriptor.java:64-283; data/code/junit-jupiter-engine/src/main/java/org/junit/jupiter/engine/descriptor/JupiterTestDescriptor.java:163-167; data/code/junit-jupiter-engine/src/main/java/org/junit/jupiter/engine/descriptor/JupiterTestDescriptor.java:85-88; data/code/junit-jupiter-engine/src/main/java/org/junit/jupiter/engine/descriptor/JupiterTestDescriptor.java:256-263; data/code/junit-jupiter-engine/src/main/java/org/junit/jupiter/engine/descriptor/JupiterTestDescriptor.java:268-268; data/code/junit-jupiter-engine/src/main/java/org/junit/jupiter/engine/descriptor/ClassBasedTestDescriptor.java:167-169; data/code/junit-jupiter-engine/src/main/java/org/junit/jupiter/engine/descriptor/MethodBasedTestDescriptor.java:147-149; data/code/junit-jupiter-engine/src/main/java/org/junit/jupiter/engine/descriptor/ClassTestDescriptor.java:63-66 | G5: JupiterTestDescriptor fixes algorithms in final methods (getExecutionMode, getLegacyReportingName) and in copyIncludingDescendants, which calls the abstract primitive withUniqueId; subclasses override the hooks (getExplicitExecutionMode, getLegacyReportingBaseName, withUniqueId). | H5: baseline | I5: Instance as found in the original code (Part 1).
A6: Original code | B6: Template Method | C6: Behavioral | D6: A5 Child Ordering Skeleton | E6: AbstractClass=org.junit.jupiter.engine.discovery.AbstractOrderingVisitor; TemplateMethod=org.junit.jupiter.engine.discovery.AbstractOrderingVisitor#orderChildrenTestDescriptors; PrimitiveOperation=org.junit.jupiter.engine.discovery.AbstractOrderingVisitor#shouldNonMatchingDescriptorsComeBeforeOrderedOnes; ConcreteClass=org.junit.jupiter.engine.discovery.ClassOrderingVisitor; ConcreteClass=org.junit.jupiter.engine.discovery.MethodOrderingVisitor | F6: data/code/junit-jupiter-engine/src/main/java/org/junit/jupiter/engine/discovery/AbstractOrderingVisitor.java:39-222; data/code/junit-jupiter-engine/src/main/java/org/junit/jupiter/engine/discovery/AbstractOrderingVisitor.java:72-119; data/code/junit-jupiter-engine/src/main/java/org/junit/jupiter/engine/discovery/AbstractOrderingVisitor.java:126-126; data/code/junit-jupiter-engine/src/main/java/org/junit/jupiter/engine/discovery/ClassOrderingVisitor.java:38-165; data/code/junit-jupiter-engine/src/main/java/org/junit/jupiter/engine/discovery/MethodOrderingVisitor.java:41-174 | G6: AbstractOrderingVisitor.orderChildrenTestDescriptors runs a fixed ordering algorithm (select, wrap, sort, unwrap, merge) and asks the abstract hook shouldNonMatchingDescriptorsComeBeforeOrderedOnes, which ClassOrderingVisitor and MethodOrderingVisitor answer differently. | H6: baseline | I6: Instance as found in the original code (Part 1).
A7: Original code | B7: Observer | C7: Behavioral | D7: A6 Discovery Event Notification | E7: Observer=org.junit.platform.launcher.LauncherDiscoveryListener; Observer (base)=org.junit.platform.engine.EngineDiscoveryListener; ConcreteObserver=org.junit.platform.launcher.core.DiscoveryIssueCollector; ConcreteObserver=org.junit.platform.launcher.core.DiscoveryIssueReportingDiscoveryListener; Subject (attach)=org.junit.platform.launcher.core.DefaultLauncher#registerLauncherDiscoveryListeners; Subject (notify)=org.junit.platform.launcher.core.EngineDiscoveryOrchestrator#discoverEngineRoot; Subject (notify, in engine)=org.junit.platform.engine.support.discovery.EngineDiscoveryRequestResolution; Multicaster=org.junit.platform.launcher.listeners.discovery.CompositeLauncherDiscoveryListener | F7: data/code/junit-platform-launcher/src/main/java/org/junit/platform/launcher/LauncherDiscoveryListener.java:42-91; data/code/junit-platform-engine/src/main/java/org/junit/platform/engine/EngineDiscoveryListener.java:31-67; data/code/junit-platform-launcher/src/main/java/org/junit/platform/launcher/core/DiscoveryIssueCollector.java:25-65; data/code/junit-platform-launcher/src/main/java/org/junit/platform/launcher/core/DiscoveryIssueReportingDiscoveryListener.java:49-131; data/code/junit-platform-launcher/src/main/java/org/junit/platform/launcher/core/DefaultLauncher.java:73-77; data/code/junit-platform-launcher/src/main/java/org/junit/platform/launcher/core/EngineDiscoveryOrchestrator.java:189-214; data/code/junit-platform-engine/src/main/java/org/junit/platform/engine/support/discovery/EngineDiscoveryRequestResolution.java:60-263; data/code/junit-platform-launcher/src/main/java/org/junit/platform/launcher/listeners/discovery/CompositeLauncherDiscoveryListener.java:29-67 | G7: Discovery progress (launcher/engine discovery started and finished, selector processed, issues) is pushed to registered LauncherDiscoveryListeners that the orchestrator only knows by interface. | H7: baseline | I7: Instance as found in the original code (Part 1).
A8: Original code | B8: Adapter | C8: Structural | D8: A7 Orderer Descriptor Wrappers | E8: Target=org.junit.jupiter.api.ClassDescriptor; Target=org.junit.jupiter.api.MethodDescriptor; Adapter (base)=org.junit.jupiter.engine.discovery.AbstractAnnotatedDescriptorWrapper; Adapter=org.junit.jupiter.engine.discovery.DefaultClassDescriptor; Adapter=org.junit.jupiter.engine.discovery.DefaultMethodDescriptor; Adaptee=org.junit.jupiter.engine.descriptor.ClassBasedTestDescriptor; Adaptee=org.junit.jupiter.engine.descriptor.MethodBasedTestDescriptor; Client=org.junit.jupiter.engine.discovery.ClassOrderingVisitor | F8: data/code/junit-jupiter-api/src/main/java/org/junit/jupiter/api/ClassDescriptor.java:28-87; data/code/junit-jupiter-api/src/main/java/org/junit/jupiter/api/MethodDescriptor.java:29-90; data/code/junit-jupiter-engine/src/main/java/org/junit/jupiter/engine/discovery/AbstractAnnotatedDescriptorWrapper.java:28-65; data/code/junit-jupiter-engine/src/main/java/org/junit/jupiter/engine/discovery/DefaultClassDescriptor.java:23-39; data/code/junit-jupiter-engine/src/main/java/org/junit/jupiter/engine/discovery/DefaultMethodDescriptor.java:25-41; data/code/junit-jupiter-engine/src/main/java/org/junit/jupiter/engine/descriptor/ClassBasedTestDescriptor.java:89-601; data/code/junit-jupiter-engine/src/main/java/org/junit/jupiter/engine/descriptor/MethodBasedTestDescriptor.java:56-217; data/code/junit-jupiter-engine/src/main/java/org/junit/jupiter/engine/discovery/ClassOrderingVisitor.java:38-165 | G8: User ClassOrderer/MethodOrderer code expects the public ClassDescriptor/MethodDescriptor API; the wrappers expose internal descriptors through it so internal classes never leak to user code. | H8: baseline | I8: Instance as found in the original code (Part 1).
A9: Original code | B9: Template Method | C9: Behavioral | D9: B1 Hierarchical Engine Execution Skeleton | E9: AbstractClass=org.junit.platform.engine.support.hierarchical.HierarchicalTestEngine; TemplateMethod=org.junit.platform.engine.support.hierarchical.HierarchicalTestEngine#execute; PrimitiveOperation=org.junit.platform.engine.support.hierarchical.HierarchicalTestEngine#createExecutionContext; ConcreteClass=org.junit.jupiter.engine.JupiterTestEngine | F9: data/code/junit-platform-engine/src/main/java/org/junit/platform/engine/support/hierarchical/HierarchicalTestEngine.java:31-119; data/code/junit-platform-engine/src/main/java/org/junit/platform/engine/support/hierarchical/HierarchicalTestEngine.java:53-63; data/code/junit-platform-engine/src/main/java/org/junit/platform/engine/support/hierarchical/HierarchicalTestEngine.java:117-117; data/code/junit-jupiter-engine/src/main/java/org/junit/jupiter/engine/JupiterTestEngine.java:44-108 | G9: final HierarchicalTestEngine.execute fixes the run order (executor service, context, collector factory, HierarchicalTestExecutor); JupiterTestEngine only supplies the steps. Overlaps B2. | H9: baseline | I9: Instance as found in the original code (Part 1).
A10: Original code | B10: Factory Method | C10: Creational | D10: B2 Engine Collaborator Factory Methods | E10: Creator (factory method)=org.junit.platform.engine.support.hierarchical.HierarchicalTestEngine#createExecutorService; ConcreteCreator=org.junit.jupiter.engine.JupiterTestEngine#createExecutorService; ConcreteCreator=org.junit.jupiter.engine.JupiterTestEngine#createExecutionContext; ConcreteCreator=org.junit.jupiter.engine.JupiterTestEngine#createThrowableCollectorFactory; ConcreteProduct=org.junit.jupiter.engine.execution.JupiterEngineExecutionContext | F10: data/code/junit-platform-engine/src/main/java/org/junit/platform/engine/support/hierarchical/HierarchicalTestEngine.java:83-85; data/code/junit-jupiter-engine/src/main/java/org/junit/jupiter/engine/JupiterTestEngine.java:80-87; data/code/junit-jupiter-engine/src/main/java/org/junit/jupiter/engine/JupiterTestEngine.java:90-93; data/code/junit-jupiter-engine/src/main/java/org/junit/jupiter/engine/JupiterTestEngine.java:99-101; data/code/junit-jupiter-engine/src/main/java/org/junit/jupiter/engine/execution/JupiterEngineExecutionContext.java:30-209 | G10: The template in B1 asks overridable create* methods which objects to use; JupiterTestEngine overrides them to choose a parallel/same-thread executor, its JupiterEngineExecutionContext and its throwable-collector factory. Overlaps B1. | H10: baseline | I10: Instance as found in the original code (Part 1).
A11: Original code | B11: Strategy | C11: Behavioral | D11: B3 Test Executor Services | E11: Strategy=org.junit.platform.engine.support.hierarchical.HierarchicalTestExecutorService; ConcreteStrategy=org.junit.platform.engine.support.hierarchical.SameThreadHierarchicalTestExecutorService; ConcreteStrategy=org.junit.platform.engine.support.hierarchical.ForkJoinPoolHierarchicalTestExecutorService; ConcreteStrategy=org.junit.platform.engine.support.hierarchical.WorkerThreadPoolHierarchicalTestExecutorService; Context=org.junit.platform.engine.support.hierarchical.HierarchicalTestExecutor; Context=org.junit.platform.engine.support.hierarchical.NodeTestTask#executeRecursively | F11: data/code/junit-platform-engine/src/main/java/org/junit/platform/engine/support/hierarchical/HierarchicalTestExecutorService.java:34-118; data/code/junit-platform-engine/src/main/java/org/junit/platform/engine/support/hierarchical/SameThreadHierarchicalTestExecutorService.java:29-50; data/code/junit-platform-engine/src/main/java/org/junit/platform/engine/support/hierarchical/ForkJoinPoolHierarchicalTestExecutorService.java:51-331; data/code/junit-platform-engine/src/main/java/org/junit/platform/engine/support/hierarchical/WorkerThreadPoolHierarchicalTestExecutorService.java:70-901; data/code/junit-platform-engine/src/main/java/org/junit/platform/engine/support/hierarchical/HierarchicalTestExecutor.java:36-71; data/code/junit-platform-engine/src/main/java/org/junit/platform/engine/support/hierarchical/NodeTestTask.java:157-189 | G11: Sequential vs parallel scheduling is swappable behind HierarchicalTestExecutorService; NodeTestTask and HierarchicalTestExecutor only call submit/invokeAll. | H11: baseline | I11: Instance as found in the original code (Part 1).
A12: Original code | B12: Strategy | C12: Behavioral | D12: B4 Parallelism Configuration Strategy | E12: Strategy=org.junit.platform.engine.support.hierarchical.ParallelExecutionConfigurationStrategy; ConcreteStrategy (enum FIXED/DYNAMIC/CUSTOM)=org.junit.platform.engine.support.hierarchical.DefaultParallelExecutionConfigurationStrategy; Selection=org.junit.platform.engine.support.hierarchical.DefaultParallelExecutionConfigurationStrategy#getStrategy; Context=org.junit.platform.engine.support.hierarchical.ParallelHierarchicalTestExecutorServiceFactory | F12: data/code/junit-platform-engine/src/main/java/org/junit/platform/engine/support/hierarchical/ParallelExecutionConfigurationStrategy.java:25-33; data/code/junit-platform-engine/src/main/java/org/junit/platform/engine/support/hierarchical/DefaultParallelExecutionConfigurationStrategy.java:33-228; data/code/junit-platform-engine/src/main/java/org/junit/platform/engine/support/hierarchical/DefaultParallelExecutionConfigurationStrategy.java:223-226; data/code/junit-platform-engine/src/main/java/org/junit/platform/engine/support/hierarchical/ParallelHierarchicalTestExecutorServiceFactory.java:33-123 | G12: How parallelism is computed (FIXED, DYNAMIC from CPU count, CUSTOM user class) is chosen by configuration; each enum constant implements createConfiguration. | H12: baseline | I12: Instance as found in the original code (Part 1).
... A143: Code after Change2 | B143: Adapter | C143: Structural | D143: N2 Managed Resource Holder | E143: Target=java.lang.AutoCloseable; Target=org.junit.jupiter.api.extension.ExtensionContext.Store.CloseableResource; Adapter=org.junit.jupiter.api.extension.support.ManagedResourceExtension.Holder; Adaptee=org.junit.jupiter.api.extension.support.ResourceFactory#destroy; Client=org.junit.jupiter.engine.descriptor.AbstractExtensionContext#createCloseAction | F143: java.lang.AutoCloseable (JDK); Part2/code/junit-jupiter-api/src/main/java/org/junit/jupiter/api/extension/ExtensionContext.java:544-553; Part2/code/junit-jupiter-api/src/main/java/org/junit/jupiter/api/extension/support/ManagedResourceExtension.java:71-94; Part2/code/junit-jupiter-api/src/main/java/org/junit/jupiter/api/extension/support/ResourceFactory.java:47-51; Part2/code/junit-jupiter-engine/src/main/java/org/junit/jupiter/engine/descriptor/AbstractExtensionContext.java:103-123 | G143: The store's close action only knows AutoCloseable.close() / Store.CloseableResource.close(); ResourceFactory offers destroy(T resource). Holder binds the resource to its factory and exposes close() that calls factory.destroy(resource), so any factory's cleanup runs through JUnit's existing close mechanism (both close paths, so it also works with auto-close disabled). | H143: newly_introduced | I143: Introduced by CH02.
A145: Source: One row per instance per version (data/build_part2_csv.py)

Sheet cross_language
A1: pattern_name | B1: instance_name | C1: language | D1: snippet_path | E1: source_loc | F1: max_function_cc | G1: runtime_compiler | H1: test_command | I1: test_result | J1: median_process_ms | K1: language_notes
A2: Observer | B2: C1 Test Execution Listeners | C2: Java | D2: Part3/observer-test-listeners/java/src/observer/BrokenListener.java; Part3/observer-test-listeners/java/src/observer/CompositeTestExecutionListener.java; Part3/observer-test-listeners/java/src/observer/EventFormatException.java; Part3/observer-test-listeners/java/src/observer/EventRunner.java; Part3/observer-test-listeners/java/src/observer/LoggingListener.java; Part3/observer-test-listeners/java/src/observer/ObserverDemo.java; Part3/observer-test-listeners/java/src/observer/Status.java; Part3/observer-test-listeners/java/src/observer/SummaryListener.java; Part3/observer-test-listeners/java/src/observer/TestExecutionListener.java | E2: 211 | F2: 7 | G2: openjdk version "25.0.4.1" 2026-08-18 LTS | H2: (cd Part3/observer-test-listeners/java) javac -d out src/observer/*.java test/observer/*.java && java -cp out observer.ObserverTest | I2: 3/3 passed (Part3/evidence/test_results/Observer_Java.txt) | J2: 36 | K2: Static typing: observer is an interface with default no-op methods, checked by the compiler; notifyEach takes a Consumer lambda; catches RuntimeException; listener name via reflection; garbage collected.
A3: Observer | B3: C1 Test Execution Listeners | C3: Python | D3: Part3/observer-test-listeners/python/listeners.py; Part3/observer-test-listeners/python/runner.py; Part3/observer-test-listeners/python/main.py | E3: 125 | F3: 8 | G3: Python 3.14.2 | H3: (cd Part3/observer-test-listeners/python) python3 -m unittest -v test_observer | I3: 3/3 passed (Part3/evidence/test_results/Observer_Python.txt) | J3: 21.8 | K3: Duck typing: base class only supplies no-op methods, no ABC (callbacks are optional); a class not inheriting from it still works; misspelt callbacks only fail at run time; catches Exception; garbage collected.
A4: Observer | B4: C1 Test Execution Listeners | C4: JavaScript | D4: Part3/observer-test-listeners/javascript/src/app.js; Part3/observer-test-listeners/javascript/src/listeners.js; Part3/observer-test-listeners/javascript/src/main.js; Part3/observer-test-listeners/javascript/src/runner.js | E4: 151 | F4: 8 | G4: Node.js v26.11.1 | H4: (cd Part3/observer-test-listeners/javascript) node --test test/observer.test.js | I4: 3/3 passed (Part3/evidence/test_results/Observer_JavaScript.txt) | J4: 93.2 | K4: Classes without interfaces: nothing enforces the contract, a plain object with one method is accepted; #private fields; catch receives any thrown value; listener name via constructor.name; synchronous to keep output order; garbage collected.
A5: Observer | B5: C1 Test Execution Listeners | C5: C++ | D5: Part3/observer-test-listeners/cpp/listeners.hpp; Part3/observer-test-listeners/cpp/listeners.cpp; Part3/observer-test-listeners/cpp/runner.hpp; Part3/observer-test-listeners/cpp/runner.cpp; Part3/observer-test-listeners/cpp/main.cpp | E5: 236 | F5: 10 | G5: Apple clang version 21.0.0 (clang-2100.3.34.2), -std=c++20 (no -O flag, as in the README) | H5: (cd Part3/observer-test-listeners/cpp) clang++ -std=c++20 -Wall -Wextra -pedantic -o observer main.cpp listeners.cpp runner.cpp && clang++ -std=c++20 -Wall -Wextra -pedantic -o observer_test test_main.cpp listeners.cpp runner.cpp && ./observer_test | I5: 3/3 passed (Part3/evidence/test_results/Observer_Cpp.txt) | J5: 5.1 | K5: Abstract base class with virtual no-op callbacks and override checking; name() is pure virtual (no portable runtime class name); ownership explicit: shared_ptr in the composite, runner borrows by reference; catches std::exception; std::function for notifyEach.
A6: Composite | B6: A1 Test Descriptor Tree | C6: Java | D6: Part3/composite-test-tree/java/src/composite/CompositeDemo.java; Part3/composite-test-tree/java/src/composite/TestCase.java; Part3/composite-test-tree/java/src/composite/TestContainer.java; Part3/composite-test-tree/java/src/composite/TestNode.java; Part3/composite-test-tree/java/src/composite/TreeFormatException.java; Part3/composite-test-tree/java/src/composite/TreeParser.java | E6: 228 | F6: 22 | G6: openjdk version "25.0.4.1" 2026-08-18 LTS | H6: (cd Part3/composite-test-tree/java) javac -d out src/composite/*.java test/composite/*.java && java -cp out composite.CompositeTest | I6: 3/3 passed (Part3/evidence/test_results/Composite_Java.txt) | J6: 34 | K6: Component is an interface; safe Composite (addChild only on TestContainer; JUnit uses the transparent form); leaf is an immutable record; parser uses pattern-matching instanceof; removed children are garbage collected.
A7: Composite | B7: A1 Test Descriptor Tree | C7: Python | D7: Part3/composite-test-tree/python/nodes.py; Part3/composite-test-tree/python/tree_parser.py; Part3/composite-test-tree/python/main.py | E7: 141 | F7: 22 | G7: Python 3.14.2 | H7: (cd Part3/composite-test-tree/python) python3 -m unittest -v test_composite | I7: 3/3 passed (Part3/evidence/test_results/Composite_Python.txt) | J7: 21.7 | K7: Component is an abc.ABC with @abstractmethod (missing methods caught when the object is created, at run time); duck-typed recursion with sum(...); safe Composite with isinstance check; lists rebuilt instead of edited while iterating; reference counting frees removed nodes at once.
A8: Composite | B8: A1 Test Descriptor Tree | C8: JavaScript | D8: Part3/composite-test-tree/javascript/src/app.js; Part3/composite-test-tree/javascript/src/main.js; Part3/composite-test-tree/javascript/src/nodes.js; Part3/composite-test-tree/javascript/src/tree-parser.js | E8: 135 | F8: 17 | G8: Node.js v26.11.1 | H8: (cd Part3/composite-test-tree/javascript) node --test test/composite.test.js | I8: 3/3 passed (Part3/evidence/test_results/Composite_JavaScript.txt) | J8: 92.2 | K8: No interfaces: base class blocks direct construction via new.target and throws in unimplemented methods (found only when called); duck typing underneath; #children private field rebuilt with filter; safe Composite with instanceof; garbage collected.
